[
  {
    "package": {
      "name": "certifi",
      "version": "2023.5.7",
      "ecosystem": "PyPI"
    },
    "vulnerabilities": [
      {
        "modified": "2023-07-25T14:59:28Z",
        "published": "2023-07-25T14:43:53Z",
        "schema_version": "1.4.0",
        "id": "GHSA-xqr8-7jwr-rhp7",
        "aliases": [
          "CVE-2023-37920"
        ],
        "summary": "Removal of e-Tugra root certificate",
        "details": "Certifi 2023.07.22 removes root certificates from \"e-Tugra\" from the root store. These are in the process of being removed from Mozilla's trust store.\n\n e-Tugra's root certificates are being removed pursuant to an investigation prompted by reporting of security issues in their systems. Conclusions of Mozilla's investigation can be found [here](https://groups.google.com/a/mozilla.org/g/dev-security-policy/c/C-HrP1SEq1A).",
        "affected": [
          {
            "package": {
              "ecosystem": "PyPI",
              "name": "certifi",
              "purl": "pkg:pypi/certifi"
            },
            "ranges": [
              {
                "type": "ECOSYSTEM",
                "events": [
                  {
                    "introduced": "2015.04.28"
                  },
                  {
                    "fixed": "2023.07.22"
                  }
                ]
              }
            ],
            "versions": [
              "2015.04.28",
              "2015.11.20",
              "2015.11.20.1",
              "2015.9.6",
              "2015.9.6.1",
              "2015.9.6.2",
              "2016.2.28",
              "2016.8.2",
              "2016.8.31",
              "2016.8.8",
              "2016.9.26",
              "2017.1.23",
              "2017.11.5",
              "2017.4.17",
              "2017.7.27",
              "2017.7.27.1",
              "2018.1.18",
              "2018.10.15",
              "2018.11.29",
              "2018.4.16",
              "2018.8.13",
              "2018.8.24",
              "2019.11.28",
              "2019.3.9",
              "2019.6.16",
              "2019.9.11",
              "2020.11.8",
              "2020.12.5",
              "2020.4.5",
              "2020.4.5.1",
              "2020.4.5.2",
              "2020.6.20",
              "2021.10.8",
              "2021.5.30",
              "2022.12.7",
              "2022.5.18",
              "2022.5.18.1",
              "2022.6.15",
              "2022.6.15.1",
              "2022.6.15.2",
              "2022.9.14",
              "2022.9.24",
              "2023.5.7"
            ],
            "database_specific": {
              "source": "https://github.com/github/advisory-database/blob/main/advisories/github-reviewed/2023/07/GHSA-xqr8-7jwr-rhp7/GHSA-xqr8-7jwr-rhp7.json"
            }
          }
        ],
        "references": [
          {
            "type": "WEB",
            "url": "https://github.com/certifi/python-certifi/security/advisories/GHSA-xqr8-7jwr-rhp7"
          },
          {
            "type": "WEB",
            "url": "https://github.com/certifi/python-certifi/commit/8fb96ed81f71e7097ed11bc4d9b19afd7ea5c909"
          },
          {
            "type": "PACKAGE",
            "url": "https://github.com/certifi/python-certifi"
          }
        ],
        "database_specific": {
          "cwe_ids": [],
          "github_reviewed": true,
          "github_reviewed_at": "2023-07-25T14:43:53Z",
          "nvd_published_at": null,
          "severity": "LOW"
        }
      }
    ],
    "groups": [
      {
        "ids": [
          "GHSA-xqr8-7jwr-rhp7"
        ]
      }
    ]
  },
  {
    "package": {
      "name": "kerberos",
      "version": "1.3.1",
      "ecosystem": "PyPI"
    },
    "vulnerabilities": [
      {
        "modified": "2021-07-25T23:34:38Z",
        "published": "2017-08-25T18:29:00Z",
        "schema_version": "1.4.0",
        "id": "PYSEC-2017-49",
        "aliases": [
          "CVE-2015-3206"
        ],
        "details": "The checkPassword function in python-kerberos does not authenticate the KDC it attempts to communicate with, which allows remote attackers to cause a denial of service (bad response), or have other unspecified impact by performing a man-in-the-middle attack.",
        "affected": [
          {
            "package": {
              "ecosystem": "PyPI",
              "name": "kerberos",
              "purl": "pkg:pypi/kerberos"
            },
            "ranges": [
              {
                "type": "ECOSYSTEM",
                "events": [
                  {
                    "introduced": "0.0"
                  }
                ]
              }
            ],
            "versions": [
              "1.1.1",
              "1.1.2",
              "1.2.0",
              "1.2.2",
              "1.2.3",
              "1.2.4",
              "1.2.5",
              "1.3.0",
              "1.3.1"
            ],
            "database_specific": {
              "source": "https://github.com/pypa/advisory-database/blob/main/vulns/kerberos/PYSEC-2017-49.yaml"
            }
          }
        ],
        "references": [
          {
            "type": "WEB",
            "url": "https://pypi.python.org/pypi/kerberos"
          },
          {
            "type": "REPORT",
            "url": "https://github.com/apple/ccs-pykerberos/issues/31"
          },
          {
            "type": "REPORT",
            "url": "https://bugzilla.redhat.com/show_bug.cgi?id=1223802"
          },
          {
            "type": "WEB",
            "url": "http://www.securityfocus.com/bid/74760"
          },
          {
            "type": "WEB",
            "url": "http://www.openwall.com/lists/oss-security/2015/05/21/3"
          }
        ]
      }
    ],
    "groups": [
      {
        "ids": [
          "PYSEC-2017-49"
        ]
      }
    ]
  }
]