[
  {
    "package": {
      "name": "configobj",
      "version": "5.0.8",
      "ecosystem": "PyPI"
    },
    "vulnerabilities": [
      {
        "modified": "2023-11-08T04:11:58Z",
        "published": "2023-04-03T06:30:19Z",
        "schema_version": "1.6.0",
        "id": "GHSA-c33w-24p9-8m24",
        "aliases": [
          "CVE-2023-26112"
        ],
        "summary": "configobj ReDoS exploitable by developer using values in a server-side configuration file",
        "details": "All versions of the package configobj are vulnerable to Regular Expression Denial of Service (ReDoS) via the validate function, using (.+?)\\((.*)\\). **Note:** This is only exploitable in the case of a developer, putting the offending value in a server side configuration file.",
        "affected": [
          {
            "package": {
              "ecosystem": "PyPI",
              "name": "configobj",
              "purl": "pkg:pypi/configobj"
            },
            "ranges": [
              {
                "type": "ECOSYSTEM",
                "events": [
                  {
                    "introduced": "0"
                  },
                  {
                    "last_affected": "5.0.8"
                  }
                ]
              }
            ],
            "versions": [
              "4.4.0",
              "4.5.0",
              "4.5.1",
              "4.5.2",
              "4.5.3",
              "4.6.0",
              "4.7.0",
              "4.7.1",
              "4.7.2",
              "5.0.0",
              "5.0.1",
              "5.0.2",
              "5.0.3",
              "5.0.4",
              "5.0.5",
              "5.0.6",
              "5.0.7",
              "5.0.8"
            ],
            "database_specific": {
              "source": "https://github.com/github/advisory-database/blob/main/advisories/github-reviewed/2023/04/GHSA-c33w-24p9-8m24/GHSA-c33w-24p9-8m24.json"
            }
          }
        ],
        "severity": [
          {
            "type": "CVSS_V3",
            "score": "CVSS:3.1/AV:N/AC:H/PR:N/UI:N/S:U/C:N/I:N/A:L"
          }
        ],
        "references": [
          {
            "type": "ADVISORY",
            "url": "https://nvd.nist.gov/vuln/detail/CVE-2023-26112"
          },
          {
            "type": "WEB",
            "url": "https://github.com/DiffSK/configobj/issues/232"
          },
          {
            "type": "PACKAGE",
            "url": "https://github.com/DiffSK/configobj"
          },
          {
            "type": "WEB",
            "url": "https://lists.fedoraproject.org/archives/list/package-announce@lists.fedoraproject.org/message/6BO4RLMYEJODCNUE3DJIIUUFVTPAG6VN/"
          },
          {
            "type": "WEB",
            "url": "https://lists.fedoraproject.org/archives/list/package-announce@lists.fedoraproject.org/message/NZHY7B33EFY4LESP2NI4APQUPRROTAZK/"
          },
          {
            "type": "WEB",
            "url": "https://lists.fedoraproject.org/archives/list/package-announce@lists.fedoraproject.org/message/PYU4IHVLOTYMFPH7KDOJGKZQR4GKWPFK/"
          },
          {
            "type": "WEB",
            "url": "https://security.snyk.io/vuln/SNYK-PYTHON-CONFIGOBJ-3252494"
          }
        ],
        "database_specific": {
          "cwe_ids": [
            "CWE-1333"
          ],
          "github_reviewed": true,
          "github_reviewed_at": "2023-04-04T21:40:45Z",
          "nvd_published_at": "2023-04-03T05:15:00Z",
          "severity": "LOW"
        }
      }
    ],
    "groups": [
      {
        "ids": [
          "GHSA-c33w-24p9-8m24"
        ],
        "aliases": [
          "CVE-2023-26112",
          "GHSA-c33w-24p9-8m24"
        ]
      }
    ]
  },
  {
    "package": {
      "name": "pydrive2",
      "version": "1.17.0",
      "ecosystem": "PyPI"
    },
    "vulnerabilities": [
      {
        "modified": "2023-12-05T23:58:16Z",
        "published": "2023-12-05T23:43:07Z",
        "schema_version": "1.6.0",
        "id": "GHSA-v5f6-hjmf-9mc5",
        "aliases": [
          "CVE-2023-49297"
        ],
        "summary": "PyDrive2's unsafe YAML deserialization in LoadSettingsFile allows arbitrary code execution",
        "details": "### Summary\nUnsafe YAML deserilization will result in arbitrary code execution. A maliciously crafted YAML file can cause arbitrary code execution if PyDrive2 is run in the same directory as it, or if it is loaded in via `LoadSettingsFile`.\n\n### Details\nThe loader being imported from the `yaml` library is `CLoader`: https://github.com/iterative/PyDrive2/blob/30c0f487c0666c0d1944ef774107359f39adc2fa/pydrive2/settings.py#L5\n\nThis loader is then used to load a user supplied file: https://github.com/iterative/PyDrive2/blob/30c0f487c0666c0d1944ef774107359f39adc2fa/pydrive2/settings.py#L108-L121\n\nCLoader is considered unsafe. It will allow any Python code inside of it to be executed. This loading behaviour also happens automatically, the file only needs to be present for this vulnerability to occur.\n\nhttps://github.com/iterative/PyDrive2/blob/30c0f487c0666c0d1944ef774107359f39adc2fa/pydrive2/settings.py#L9\n\nReference: https://www.exploit-db.com/docs/english/47655-yaml-deserialization-attack-in-python.pdf\n\n### PoC\n1. Create a malicious `settings.yaml` file:\n\n```yaml\n!!python/object/new:os.system [echo poc]\n```\n2. Initialize a `GoogleAuth` object .\n```python\nfrom pydrive2.auth import GoogleAuth\n\ngauth = GoogleAuth()\n```\n3. Execute the code with the settings file present in your directory. The code inside the file will be executed:\n```\n[evan@ejedev PyDrive2]$ ls\nCHANGES  client_secrets.json  CONTRIBUTING.rst  docs  examples  LICENSE  main.py  MANIFEST.in  pydrive2  pyproject.toml  pytest.ini  README.rst  settings.yaml  setup.py  tox.ini\n[evan@ejedev PyDrive2]$ cat settings.yaml\n!!python/object/new:os.system [echo poc]\n[evan@ejedev PyDrive2]$ cat main.py \nfrom pydrive2.auth import GoogleAuth\n\n\ngauth = GoogleAuth()\n[evan@ejedev PyDrive2]$ python3 main.py \npoc\n```\nAlternatively, the file can be loaded in directly via `pydrive2.settings.LoadSettingsFile` \n\n### Impact\nThis is a deserilization attack that will affect any user who initializes GoogleAuth from this package while a malicious `yaml` file is present in the same directory. As it does not require it to be directly loaded through the code, only present, I believe this produces an extra element of risk. ",
        "affected": [
          {
            "package": {
              "ecosystem": "PyPI",
              "name": "pydrive2",
              "purl": "pkg:pypi/pydrive2"
            },
            "versions": [
              "1.17.0"
            ],
            "database_specific": {
              "source": "https://github.com/github/advisory-database/blob/main/advisories/github-reviewed/2023/12/GHSA-v5f6-hjmf-9mc5/GHSA-v5f6-hjmf-9mc5.json"
            }
          },
          {
            "package": {
              "ecosystem": "PyPI",
              "name": "pydrive2",
              "purl": "pkg:pypi/pydrive2"
            },
            "ranges": [
              {
                "type": "ECOSYSTEM",
                "events": [
                  {
                    "introduced": "0"
                  },
                  {
                    "fixed": "1.16.2"
                  }
                ]
              }
            ],
            "versions": [
              "0.14.0",
              "1.10.0",
              "1.10.1",
              "1.10.2",
              "1.11.0",
              "1.11.1",
              "1.11.2",
              "1.12.0",
              "1.12.1",
              "1.13.0",
              "1.14.0",
              "1.15.0",
              "1.15.1",
              "1.15.2",
              "1.15.3",
              "1.15.4",
              "1.16.0",
              "1.16.1",
              "1.4.0",
              "1.4.1",
              "1.4.10",
              "1.4.11",
              "1.4.12",
              "1.4.13",
              "1.4.14",
              "1.4.2",
              "1.4.4",
              "1.4.5",
              "1.4.6",
              "1.4.7",
              "1.4.8",
              "1.4.9",
              "1.6.0",
              "1.6.1",
              "1.6.2",
              "1.6.3",
              "1.7.0",
              "1.7.2",
              "1.7.3",
              "1.8.0",
              "1.8.1",
              "1.8.2",
              "1.8.3",
              "1.9.0",
              "1.9.1",
              "1.9.2",
              "1.9.3",
              "1.9.4"
            ],
            "database_specific": {
              "source": "https://github.com/github/advisory-database/blob/main/advisories/github-reviewed/2023/12/GHSA-v5f6-hjmf-9mc5/GHSA-v5f6-hjmf-9mc5.json"
            }
          }
        ],
        "severity": [
          {
            "type": "CVSS_V3",
            "score": "CVSS:3.1/AV:L/AC:L/PR:N/UI:R/S:U/C:L/I:N/A:N"
          }
        ],
        "references": [
          {
            "type": "WEB",
            "url": "https://github.com/iterative/PyDrive2/security/advisories/GHSA-v5f6-hjmf-9mc5"
          },
          {
            "type": "ADVISORY",
            "url": "https://nvd.nist.gov/vuln/detail/CVE-2023-49297"
          },
          {
            "type": "WEB",
            "url": "https://github.com/iterative/PyDrive2/commit/c57355dc2033ad90b7050d681b2c3ba548ff0004"
          },
          {
            "type": "PACKAGE",
            "url": "https://github.com/iterative/PyDrive2"
          }
        ],
        "database_specific": {
          "cwe_ids": [
            "CWE-502"
          ],
          "github_reviewed": true,
          "github_reviewed_at": "2023-12-05T23:43:07Z",
          "nvd_published_at": "2023-12-05T21:15:07Z",
          "severity": "LOW"
        }
      }
    ],
    "groups": [
      {
        "ids": [
          "GHSA-v5f6-hjmf-9mc5"
        ],
        "aliases": [
          "CVE-2023-49297",
          "GHSA-v5f6-hjmf-9mc5"
        ]
      }
    ]
  }
]